} catch(err) {
    Test.error(err);
    Test.current_section.push({error:"Could not complete tests."});
}

//-------------------------------------------------
// ENDING TEST SECTION
//-------------------------------------------------

